<mujoco>
  <compiler autolimits="true"/>

  <asset>
    <texture name="grid" type="2d" builtin="checker" width="512" height="512" rgb1=".1 .2 .3" rgb2=".2 .3 .4"/>
    <material name="grid" texture="grid" texrepeat="1 1" texuniform="true" reflectance="0"/>
  </asset>

  <worldbody>
    <geom type="plane" pos="0 0 -1" size="3 3 .01" material="grid"/>
    <light name="top light" pos="0 0 4" mode="trackcom" diffuse=".7 .7 .7"/>


    <geom name="rail1" type="cylinder" pos="0 0.02 0" size=".01 1" quat='0.707 0 0.707 0' rgba=".1 .9 0.5 0.7"/>
    <geom name="rail2" type="cylinder" pos="0 -0.02 0" size=".01 1" quat='0.707 0 0.707 0' rgba=".1 .9 0.5 0.7"/>


    <body name='cart' pos='0 0 0.03'>

        <!--  cart  -->
        <joint name='slider' type='slide' limited='true' pos='0 0 0'
               axis='1 0 0' range='-1 1' />
        <geom name="cart" type="box" pos="0 0 0" size=".06 0.04 0.02" rgba=".9 .4 0.5 1"/>
        <site name='cart sensor' type='box' pos='0 0 0'
              size='.06 0.04 0.02' rgba='1 1 1 0' />
               
        <!--  pole  -->
        <body name='pole' pos='0 -0.05 0'>
            <joint name='hinge' type='hinge' pos='0 0 0' axis='0 1 0'/>
            <site type='sphere' size='.02' pos='0 0 0' rgba='.9 .4 0.5 1'/>
            <geom name='cpole' type='capsule' fromto='0 0 0 0 0 0.4'
                size='0.01 0.2' rgba='0 0.7 0.7 1' />
            <site type='sphere' name='tip' size='.02' pos='0 0 0.4' rgba='1 1 1 1'/>

        </body>
        
    </body>
  </worldbody>

    <actuator>
        <motor name='slide' joint='slider' gear='5' ctrllimited='true' ctrlrange='-1 1' />
    </actuator>

    <sensor>
        <accelerometer name="accelerometer" site="cart sensor"/>
        <touch name="collision" site="cart sensor"/>
  </sensor>

  <keyframe>
    <key name="hang_down" qpos="0 1.57"/>
  </keyframe>

</mujoco>
